<?xml version="1.0"?>
<robot name="truck">
  <!-- LINKS SECTION -->
  <link name="base">
    <visual>
      <origin rpy="1.5708 0 1.5708" xyz="0 0 0"/>
      <geometry>
        <mesh filename="file://hardware/model/meshes/group5.obj"/>
      </geometry>
    </visual>
    <inertial>
      <mass value="2.05371"/>
      <inertia ixx="0.00627" iyy="0.04284" izz="0.04836" ixy="0.00089" iyz="-0.00013" ixz="0.00036"/>
    </inertial>
    <collision>
      <origin xyz="-0.0 -0.0 0.006" rpy="0 0 0"/>
      <geometry>
        <box size="0.261 0.231 0.05"/>
      </geometry>
    </collision>
    <collision>
      <origin xyz="-0.0 0.0 0.0235" rpy="0 0 0"/>
      <geometry>
        <box size="0.5108 0.1 0.085"/>
      </geometry>
    </collision>
  </link>
  <link name="front_left_cup">
    <inertial>
      <mass value="0.01286"/>
      <inertia ixx="0.0" iyy="0.0" izz="0.0" ixy="-0.0" iyz="0.0" ixz="0.0"/>
    </inertial>
  </link>
  <link name="front_right_cup">
    <inertial>
      <mass value="0.01286"/>
      <inertia ixx="0.0" iyy="0.0" izz="0.0" ixy="0.0" iyz="-0.0" ixz="0.0"/>
    </inertial>
  </link>
  <link name="front_left_wheel">
    <visual>
      <origin rpy="1.5708 0 1.5708" xyz="-0.2025 -0.11418 0.01329"/>
      <geometry>
        <mesh filename="file://hardware/model/meshes/group3.obj"/>
      </geometry>
    </visual>
    <inertial>
      <mass value="0.10157"/>
      <inertia ixx="0.00012" iyy="0.00018" izz="0.00012" ixy="-0.0" iyz="0.0" ixz="-0.0"/>
    </inertial>
    <collision>
      <origin xyz="0.0 0.017 0.0" rpy="1.5708 0 0"/>
      <geometry>
        <cylinder radius="0.055" length="0.058"/>
      </geometry>
    </collision>
  </link>
  <link name="front_right_wheel">
    <visual>
      <origin rpy="1.5708 0 1.5708" xyz="-0.2025 0.11418 0.01329"/>
      <geometry>
        <mesh filename="file://hardware/model/meshes/group6.obj"/>
      </geometry>
    </visual>
    <inertial>
      <mass value="0.10157"/>
      <inertia ixx="0.00012" iyy="0.00018" izz="0.00012" ixy="0.0" iyz="-0.0" ixz="0.0"/>
    </inertial>
    <collision>
      <origin xyz="0.0 -0.017 0.0" rpy="1.5708 0 0"/>
      <geometry>
        <cylinder radius="0.055" length="0.058"/>
      </geometry>
    </collision>
  </link>
  <link name="rear_left_wheel">
    <visual>
      <origin rpy="1.5708 0 1.5708" xyz="0.2025 -0.11168 0.01329"/>
      <geometry>
        <mesh filename="file://hardware/model/meshes/group4.obj"/>
      </geometry>
    </visual>
    <inertial>
      <mass value="0.10194"/>
      <inertia ixx="0.00012" iyy="0.00018" izz="0.00012" ixy="0.0" iyz="0.0" ixz="-0.0"/>
    </inertial>
    <collision>
      <origin xyz="0.0 0.0195 0.0" rpy="1.5708 0 0"/>
      <geometry>
        <cylinder radius="0.055" length="0.058"/>
      </geometry>
    </collision>
  </link>
  <link name="rear_right_wheel">
    <visual>
      <origin rpy="1.5708 0 1.5708" xyz="0.2025 0.11168 0.01329"/>
      <geometry>
        <mesh filename="file://hardware/model/meshes/group1.obj"/>
      </geometry>
    </visual>
    <inertial>
      <mass value="0.10194"/>
      <inertia ixx="0.00012" iyy="0.00018" izz="0.00012" ixy="-0.0" iyz="-0.0" ixz="0.0"/>
    </inertial>
    <collision>
      <origin xyz="0.0 -0.0195 0.0" rpy="1.5708 0 0"/>
      <geometry>
        <cylinder radius="0.055" length="0.058"/>
      </geometry>
    </collision>
  </link>
  <!-- JOINTS SECTION -->
  <joint name="left_steering_joint" type="revolute">
    <parent link="base"/>
    <child link="front_left_cup"/>
    <axis xyz="0.0 0.0 1.0"/>
    <origin xyz="0.2025 0.10668 -0.01329"/>
    <limit effort="30" velocity="1.0" lower="-0.69813" upper="0.5236"/>
  </joint>
  <joint name="right_steering_joint" type="revolute">
    <parent link="base"/>
    <child link="front_right_cup"/>
    <axis xyz="-0.0 -0.0 1.0"/>
    <origin xyz="0.2025 -0.10668 -0.01329"/>
    <limit effort="30" velocity="1.0" lower="-0.5236" upper="0.69813"/>
  </joint>
  <joint name="front_left_wheel_axle" type="continuous">
    <parent link="front_left_cup"/>
    <child link="front_left_wheel"/>
    <axis xyz="-0.0 -1.0 0.0"/>
    <origin xyz="0.0 0.0075 -0.0"/>
  </joint>
  <joint name="front_right_wheel_axle" type="continuous">
    <parent link="front_right_cup"/>
    <child link="front_right_wheel"/>
    <axis xyz="-0.0 -1.0 -0.0"/>
    <origin xyz="-0.0 -0.0075 -0.0"/>
  </joint>
  <joint name="left_rear_axle" type="continuous">
    <parent link="base"/>
    <child link="rear_left_wheel"/>
    <axis xyz="0.0 1.0 0.0"/>
    <origin xyz="-0.2025 0.11168 -0.01329"/>
  </joint>
  <joint name="right_rear_axle" type="continuous">
    <parent link="base"/>
    <child link="rear_right_wheel"/>
    <axis xyz="-0.0 1.0 -0.0"/>
    <origin xyz="-0.2025 -0.11168 -0.01329"/>
  </joint>
</robot>
